Workbook
Name ____58: #REF!
Name ____IV65999: #REF!
Name ____IV66126: #REF!
Name ____IV66926: #REF!
Name ____IV67092: #REF!
Name ____IV69999: #REF!
Name ____IV79999: #REF!
Name ____IV89999: #REF!
Name ____IV99999: #REF!
Name ___10: #REF!
Name ___12: #REF!
Name ___15: #REF!
Name ___23: #REF!
Name ___3: #REF!
Name ___4: #REF!
Name ___7: #REF!
Name ___7778: #REF!
Name ___78: #REF!
Name ___79: #REF!
Name ___9: #REF!
Name ___95: #REF!
Name ___IV65999: #REF!
Name ___IV66126: #REF!
Name ___IV66926: #REF!
Name ___IV67092: #REF!
Name ___IV69999: #REF!
Name ___IV79999: #REF!
Name ___IV89998: #REF!
Name ___IV89999: #REF!
Name ___IV99999: #REF!
Name __777: #REF!
Name __8: #REF!
Name __88: #REF!
Name __9: #REF!
Name __IV65999: #REF!
Name __IV66126: #REF!
Name __IV66926: #REF!
Name __IV67092: #REF!
Name __IV69999: #REF!
Name __IV79999: #REF!
Name __IV89999: #REF!
Name __IV99999: #REF!
Name _4: #REF!
Name _7789: #REF!
Name _IV65999: #REF!
Name _IV66126: #REF!
Name _IV66926: #REF!
Name _IV67092: #REF!
Name _IV69999: #REF!
Name _IV79999: #REF!
Name _iv8888: #REF!
Name _IV89999: #REF!
Name _IV99999: #REF!
Name AS2DocOpenMode: "AS2DocumentEdit"
Name BORR: #REF!
Name catego2: '[1]Base 1'!$B$19:$D$34
Name CodCategoria: [2]NOMINA!$E$21:$E$37
Name CodContrato: [2]NOMINA!$H$21:$H$37
Name codigo: '[1]Base 1'!$B$19:$B$25
Name D: '[3]Anestesia y Ream'!$E$3:$E$66

Sheet BASE PERSONAL
A1: Cuadro para personal vinculado con la Universidad El Bosque por Nomina 2025
A2: Categoria Docente | B2: Dedicacacion No. Horas | C2: Asig Inicial por hora | D2: Valor Prestaciones 51,842% | E2: Asignación Mensual | F2: % Aumento | G2: Valor Aumento | H2: Valor Mensual | I2: Meses | J2: Valor Hora | K2: Total Meses | L2: Acum. X Persona
A3: INSTRUCTOR ASOCIADO | C3: =A5 -> 269600 | D3: =C3*51.842% -> 139766.03 | E3: =C3+D3 -> 409366.03 | F3: 0 | G3: =E3*F3 -> 0 | H3: =G3+E3 -> 409366.03 | I3: 12 | J3: 194752.55 | K3: =I3*H3 -> 4912392.4
A4: Docente/Investigador | B4: 2 | C4: =H3 -> 409366.03 | D4: 0 | E4: =C4+D4 -> 409366.03 | F4: 0.08 | G4: =E4*F4 -> 32749.283 | H4: =G4+E4 -> 442115.31 | I4: 12 | J4: 210332.75 | K4: =I4*H4 -> 5305383.8
A5: =5392000/40*B4 -> 269600 | C5: =H4 -> 442115.31 | D5: 0 | E5: =C5+D5 -> 442115.31 | F5: 0.08 | G5: =E5*F5 -> 35369.225 | H5: =G5+E5 -> 477484.54 | I5: 6 | J5: 227159.37 | K5: =I5*H5 -> 2864907.2
A6: Adriana María Cristancho Arévalo | C6: =H5 -> 477484.54 | D6: 0 | E6: =C6+D6 -> 477484.54 | F6: 0.08 | G6: =E6*F6 -> 38198.763 | H6: 0 | I6: 0 | J6: 245332.12 | K6: =I6*H6 -> 0
C7: =H6 -> 0 | D7: 0 | E7: =C7+D7 -> 0 | F7: 0.08 | G7: =E7*F7 -> 0 | H7: =G7+E7 -> 0 | I7: 0 | J7: 264958.69 | K7: =I7*H7 -> 0
I8: =SUBTOTAL(109,I3:I7) -> 30 | L8: =SUM(K3:K7) -> 13082683
A9: PROFESOR ASISTENTE | C9: =A11 -> 336400 | D9: =C9*51.842% -> 174396.49 | E9: =C9+D9 -> 510796.49 | F9: 0 | G9: =E9*F9 -> 0 | H9: =G9+E9 -> 510796.49 | I9: 12 | J9: 243190.15 | K9: =I9*H9 -> 6129557.9
A10: Docente/Investigador | B10: 2 | C10: =H9 -> 510796.49 | D10: 0 | E10: =C10+D10 -> 510796.49 | F10: 0.08 | G10: =E10*F10 -> 40863.719 | H10: =G10+E10 -> 551660.21 | I10: 12 | J10: 262645.36 | K10: =I10*H10 -> 6619922.5
A11: =6728000/40*B10 -> 336400 | C11: =H10 -> 551660.21 | D11: 0 | E11: =C11+D11 -> 551660.21 | F11: 0.08 | G11: =E11*F11 -> 44132.817 | H11: =G11+E11 -> 595793.02 | I11: 6 | J11: 283656.99 | K11: =I11*H11 -> 3574758.1
A12: Bertha Patricia Calderón Ortiz | C12: =H11 -> 595793.02 | D12: 0 | E12: =C12+D12 -> 595793.02 | F12: 0.08 | G12: =E12*F12 -> 47663.442 | H12: =G12+E12 -> 643456.47 | I12: 0 | J12: 306349.55 | K12: =I12*H12 -> 0
C13: =H12 -> 643456.47 | D13: 0 | E13: =C13+D13 -> 643456.47 | F13: 0.08 | G13: =E13*F13 -> 51476.517 | H13: =G13+E13 -> 694932.98 | I13: 0 | J13: 330857.51 | K13: =I13*H13 -> 0
I14: =SUBTOTAL(109,I9:I13) -> 30 | L14: =SUM(K9:K13) -> 16324238
A15: PROFESOR ASISTENTE | C15: =A17 -> 336400 | D15: =C15*51.842% -> 174396.49 | E15: =C15+D15 -> 510796.49 | F15: 0 | G15: =E15*F15 -> 0 | H15: =G15+E15 -> 510796.49 | I15: 12 | J15: 243190.15 | K15: =I15*H15 -> 6129557.9
A16: Docente/Investigador | B16: 2 | C16: =H15 -> 510796.49 | D16: 0 | E16: =C16+D16 -> 510796.49 | F16: 0.08 | G16: =E16*F16 -> 40863.719 | H16: =G16+E16 -> 551660.21 | I16: 12 | J16: 262645.36 | K16: =I16*H16 -> 6619922.5
A17: =6728000/40*B16 -> 336400 | C17: =H16 -> 551660.21 | D17: 0 | E17: =C17+D17 -> 551660.21 | F17: 0.08 | G17: =E17*F17 -> 44132.817 | H17: =G17+E17 -> 595793.02 | I17: 6 | J17: 283656.99 | K17: =I17*H17 -> 3574758.1
A18: María Catalina Bages Mesa | C18: =H17 -> 595793.02 | D18: 0 | E18: =C18+D18 -> 595793.02 | F18: 0.08 | G18: =E18*F18 -> 47663.442 | H18: =G18+E18 -> 643456.47 | I18: 0 | J18: 306349.55 | K18: =I18*H18 -> 0
C19: =H18 -> 643456.47 | D19: 0 | E19: =C19+D19 -> 643456.47 | F19: 0.08 | G19: =E19*F19 -> 51476.517 | H19: =G19+E19 -> 694932.98 | I19: 0 | J19: 330857.51 | K19: =I19*H19 -> 0
I20: =SUBTOTAL(109,I15:I19) -> 30 | L20: =SUM(K15:K19) -> 16324238
A21: PROFESOR ASISTENTE | C21: =A23 -> 336400 | D21: =C21*51.842% -> 174396.49 | E21: =C21+D21 -> 510796.49 | F21: 0 | G21: =E21*F21 -> 0 | H21: =G21+E21 -> 510796.49 | I21: 12 | J21: 243190.15 | K21: =I21*H21 -> 6129557.9
A22: Docente/Investigador | B22: 2 | C22: =H21 -> 510796.49 | D22: 0 | E22: =C22+D22 -> 510796.49 | F22: 0.08 | G22: =E22*F22 -> 40863.719 | H22: =G22+E22 -> 551660.21 | I22: 12 | J22: 262645.36 | K22: =I22*H22 -> 6619922.5
A23: =6728000/40*B22 -> 336400 | C23: =H22 -> 551660.21 | D23: 0 | E23: =C23+D23 -> 551660.21 | F23: 0.08 | G23: =E23*F23 -> 44132.817 | H23: =G23+E23 -> 595793.02 | I23: 6 | J23: 283656.99 | K23: =I23*H23 -> 3574758.1
A24: Lina Maria Rodríguez Granada | C24: =H23 -> 595793.02 | D24: 0 | E24: =C24+D24 -> 595793.02 | F24: 0.08 | G24: =E24*F24 -> 47663.442 | H24: =G24+E24 -> 643456.47 | I24: 0 | J24: 306349.55 | K24: =I24*H24 -> 0
C25: =H24 -> 643456.47 | D25: 0 | E25: =C25+D25 -> 643456.47 | F25: 0.08 | G25: =E25*F25 -> 51476.517 | H25: =G25+E25 -> 694932.98 | I25: 0 | J25: 330857.51 | K25: =I25*H25 -> 0
I26: =SUBTOTAL(109,I21:I25) -> 30 | L26: =SUM(K21:K25) -> 16324238
A27: PROFESOR ASOCIADO | C27: =A29 -> 2066000 | D27: =C27*51.842% -> 1071055.7 | E27: =C27+D27 -> 3137055.7 | F27: 0 | G27: =E27*F27 -> 0 | H27: =G27+E27 -> 3137055.7 | I27: 12 | J27: 298809.87 | K27: =I27*H27 -> 37644669
A28: Docente/Investigador | B28: 10 | C28: =H27 -> 3137055.7 | D28: 0 | E28: =C28+D28 -> 3137055.7 | F28: 0.08 | G28: =E28*F28 -> 250964.46 | H28: =G28+E28 -> 3388020.2 | I28: 12 | J28: 322714.66 | K28: =I28*H28 -> 40656242
A29: =8264000/40*B28 -> 2066000 | C29: =H28 -> 3388020.2 | D29: 0 | E29: =C29+D29 -> 3388020.2 | F29: 0.08 | G29: =E29*F29 -> 271041.61 | H29: =G29+E29 -> 3659061.8 | I29: 6 | J29: 348531.83 | K29: =I29*H29 -> 21954371
A30: Juan David Leongómez Peña | C30: =H29 -> 3659061.8 | D30: 0 | E30: =C30+D30 -> 3659061.8 | F30: 0.08 | G30: =E30*F30 -> 292724.94 | H30: =G30+E30 -> 3951786.7 | I30: 0 | J30: 376414.38 | K30: =I30*H30 -> 0
C31: =H30 -> 3951786.7 | D31: 0 | E31: =C31+D31 -> 3951786.7 | F31: 0.08 | G31: =E31*F31 -> 316142.94 | H31: =G31+E31 -> 4267929.7 | I31: 0 | J31: 406527.53 | K31: =I31*H31 -> 0
I32: =SUBTOTAL(109,I27:I31) -> 30 | L32: =SUM(K27:K31) -> 1.0025528e+08
A33: PROFESOR ASOCIADO | C33: =A35 -> 1239600 | D33: =C33*51.842% -> 642633.43 | E33: =C33+D33 -> 1882233.4 | F33: 0 | G33: =E33*F33 -> 0 | H33: =G33+E33 -> 1882233.4 | I33: 12 | J33: 298809.87 | K33: =I33*H33 -> 22586801
A34: Docente/Investigador | B34: 6 | C34: =H33 -> 1882233.4 | D34: 0 | E34: =C34+D34 -> 1882233.4 | F34: 0.08 | G34: =E34*F34 -> 150578.67 | H34: =G34+E34 -> 2032812.1 | I34: 12 | J34: 322714.66 | K34: =I34*H34 -> 24393745
A35: =8264000/40*B34 -> 1239600 | C35: =H34 -> 2032812.1 | D35: 0 | E35: =C35+D35 -> 2032812.1 | F35: 0.08 | G35: =E35*F35 -> 162624.97 | H35: =G35+E35 -> 2195437.1 | I35: 6 | J35: 348531.83 | K35: =I35*H35 -> 13172622
A36: Milena Vásquez Amézquita | C36: =H35 -> 2195437.1 | D36: 0 | E36: =C36+D36 -> 2195437.1 | F36: 0.08 | G36: =E36*F36 -> 175634.97 | H36: =G36+E36 -> 2371072 | I36: 0 | J36: 376414.38 | K36: =I36*H36 -> 0
C37: =H36 -> 2371072 | D37: 0 | E37: =C37+D37 -> 2371072 | F37: 0.08 | G37: =E37*F37 -> 189685.76 | H37: =G37+E37 -> 2560757.8 | I37: 0 | J37: 406527.53 | K37: =I37*H37 -> 0
I38: =SUBTOTAL(109,I33:I37) -> 30 | L38: =SUM(K33:K37) -> 60153169
A39: PROFESOR TITULAR | C39: =A41 -> 605200 | D39: =C39*51.842% -> 313747.78 | E39: =C39+D39 -> 918947.78 | F39: 0 | G39: =E39*F39 -> 0 | H39: =G39+E39 -> 918947.78 | I39: 12 | J39: 283952.15 | K39: =I39*H39 -> 11027373
A40: Docente/Investigador | B40: 2 | C40: =H39 -> 918947.78 | D40: 0 | E40: =C40+D40 -> 918947.78 | F40: 0.08 | G40: =E40*F40 -> 73515.823 | H40: =G40+E40 -> 992463.61 | I40: 12 | J40: 283952.15 | K40: =I40*H40 -> 11909563
...

Sheet RESUMEN GENERAL
A1: PROYECCIÓN PRESUPUESTAL - PROYECTOS CONVOCATORIA INTERNA
A2: Mecanismo de la convocatoria: | B2: Investigación avanzada
A3: Título del proyecto: | B3: Funciones evolutivas del habla dirigida a bebés: Impacto en la atención, las preferencias auditivas y el desarrollo lingüístico y musical temprano
A4: Investigador Principal: | B4: Juan David Leongómez Peña
A5: Correo de contacto: | B5: jleongomez@unbosque.edu.co
A6: Numero de contacto: | B6: 319 407 7102
A9: PRESUPUESTO GLOBAL DE LA PROPUESTA (LA INFORMACIÓN DE ESTA TABLA SE TRASLADA DE MANERA AUTOMÁTICA AL DILIGENCIAR LAS PESTAÑAS)
A10: Rubro | B10: Universidad El Bosque | F10: Total Universidad El Bosque | G10: Nombre de las entidades co-financiadoras | I10: Total entidades co-financiadoras | J10: Total proyecto
B11: Dinero (RECURSOS CONVOCATORIA INTERNA EFECTIVO) | C11: Tope recursos a solicitar | D11: % | E11: Especie | G11: Dinero | H11: Especie
A12: Personal científico | B12: =+'Personal científico'!T20 -> 0 | C12: 0.6 | D12: =B12*100/$B$24 -> 0 | E12: =+'Personal científico'!U20 -> 3.4526832e+08 | F12: =B12+E12 -> 3.4526832e+08 | G12: =+'Personal científico'!V20 -> 0 | H12: =+'Personal científico'!W20 -> 0 | I12: =SUM(G12:H12) -> 0 | J12: =+F12+I12 -> 3.4526832e+08
A13: Equipos especializados | B13: ='Equipos especializados'!E18 -> 239000000 | C13: 1 | D13: =B13*100/$B$24 -> 81.110432 | E13: ='Equipos especializados'!F18 -> 0 | F13: =B13+E13 -> 239000000 | G13: =+'Equipos especializados'!G18 -> 0 | H13: =+'Equipos especializados'!H18 -> 0 | I13: =SUM(G13:H13) -> 0 | J13: =+F13+I13 -> 239000000
A14: Materiales y reactivos | B14: =+'Materiales y reactivos '!F17 -> 0 | C14: 1 | D14: =B14*100/$B$24 -> 0 | E14: N/A | F14: =B14 -> 0 | G14: =+'Materiales y reactivos '!G17 -> 0 | H14: =+'Materiales y reactivos '!H17 -> 0 | I14: =SUM(G14:H14) -> 0 | J14: =+F14+I14 -> 0
A15: Salidas de campo | B15: =+'Salida de campo'!N16 -> 0 | C15: 0.5 | D15: =B15*100/$B$24 -> 0 | E15: N/A | F15: =B15 -> 0 | G15: =+'Salida de campo'!O16 -> 0 | H15: =+'Salida de campo'!P16 -> 0 | I15: =SUM(G15:H15) -> 0 | J15: =+F15+I15 -> 0
A16: Refrigerios | B16: =+Refrigerios!E18 -> 8000000 | C16: 0.1 | D16: =B16*100/$B$24 -> 2.7149936 | E16: N/A | F16: =B16 -> 8000000 | G16: =+Refrigerios!F18 -> 0 | H16: =+Refrigerios!G18 -> 0 | I16: =SUM(G16:H16) -> 0 | J16: =+F16+I16 -> 8000000
A17: Servicios técnicos | B17: =+'Servicios técnicos'!F17 -> 24000000 | C17: 0.5 | D17: =B17*100/$B$24 -> 8.1449807 | E17: N/A | F17: =B17 -> 24000000 | G17: =+'Servicios técnicos'!G17 -> 0 | H17: =+'Servicios técnicos'!H17 -> 0 | I17: =SUM(G17:H17) -> 0 | J17: =+F17+I17 -> 24000000
A18: Software | B18: =+'Software especializado '!F16 -> 0 | C18: 0.2 | D18: =B18*100/$B$24 -> 0 | E18: =+'Software especializado '!G16 -> 0 | F18: =B18+E18 -> 0 | G18: =+'Software especializado '!H16 -> 0 | H18: =+'Software especializado '!I16 -> 0 | I18: =SUM(G18:H18) -> 0 | J18: =+F18+I18 -> 0
A19: Polízas para la realización de ensayos clínicos | B19: =+'Pólizas para la realización de '!E16 -> 0 | C19: 1 | D19: =B19*100/$B$24 -> 0 | E19: N/A | F19: =B19 -> 0 | G19: =+'Pólizas para la realización de '!F16 -> 0 | H19: =+'Pólizas para la realización de '!#REF! -> #REF! | I19: =SUM(G19:H19) -> #REF! | J19: =+F19+I19 -> #REF!
A20: Apoyo a la producción científica o artística | B20: =+'Apoyo a la producción científic'!F15 -> 0 | C20: 0.3 | D20: =B20*100/$B$24 -> 0 | E20: N/A | F20: =B20 -> 0 | G20: =+'Apoyo a la producción científic'!G15 -> 0 | H20: =+'Apoyo a la producción científic'!#REF! -> #REF! | I20: =SUM(G20:H20) -> #REF! | J20: =+F20+I20 -> #REF!
A21: Apoyo a la difusión de resultados derivados de actividades de CTeI | B21: =+'Apoyo a la difusión de resultad'!N17 -> 12660000 | C21: 0.1 | D21: =B21*100/$B$24 -> 4.2964773 | E21: N/A | F21: =B21 -> 12660000 | G21: =+'Apoyo a la difusión de resultad'!O17 -> 0 | H21: =+'Apoyo a la difusión de resultad'!P17 -> 0 | I21: =SUM(G21:H21) -> 0 | J21: =+F21+I21 -> 12660000
A22: Otros | B22: ='Otros gastos'!F18 -> 0 | C22: 0.1 | D22: =B22*100/$B$24 -> 0 | E22: N/A | F22: =B22 -> 0 | G22: =+'Otros gastos'!G18 -> 0 | H22: =+'Otros gastos'!H18 -> 0 | I22: =SUM(G22:H22) -> 0 | J22: =+F22+I22 -> 0
A23: Estrategia de divulgación | B23: =+'Estrategia de divulgación'!F18 -> 11000000 | C23: 0.1 | D23: =B23*100/$B$24 -> 3.7331161 | E23: N/A | F23: =B23 -> 11000000 | G23: =+'Salida de campo'!O16 -> 0 | H23: =+'Salida de campo'!P16 -> 0 | I23: =SUM(G23:H23) -> 0 | J23: =+F23+I23 -> 11000000
A24: Total | B24: =SUM(B12:B23) -> 294660000 | E24: =SUM(E12:E23) -> 3.4526832e+08 | F24: =SUM(F12:F23) -> 6.3992832e+08 | G24: =SUM(G12:G23) -> 0 | H24: =SUM(H12:H23) -> #REF! | I24: =SUM(I12:I23) -> #REF! | J24: =SUM(J12:J23) -> #REF!
A27: Para completar la información financiera en la tabla, es necesario ingresar los datos en las pestañas correspondientes, desde donde se transferirán automáticamente a esta pestaña general. Si tiene dudas sobre el diligenciamiento de este documento, le recomendamos contactar al área administrativa y financiera de la UGPI a través del correo electrónico financiera.vri@unbosque.edu.co.

Sheet Personal científico
A1: ='RESUMEN GENERAL'!A3 -> Título del proyecto: | B1: {='RESUMEN GENERAL'!B3:J3} -> Funciones evolutivas del habla dirigida a bebés: Impacto en la atención, las preferencias auditivas y el desarrollo lingüístico y musical temprano | C1: 0 | D1: 0 | E1: 0 | F1: 0 | G1: 0 | H1: 0 | I1: 0 | J1: 0
A2: ='RESUMEN GENERAL'!A4 -> Investigador Principal: | B2: {='RESUMEN GENERAL'!B4:J4} -> Juan David Leongómez Peña | C2: 0 | D2: 0 | E2: 0 | F2: 0 | G2: 0 | H2: 0 | I2: 0 | J2: 0
A4: Personal
A5: * Pago de horas docentes para apoyo a la ejecución del proyecto. * Vinculación de profesionales menores a 28 años, recién egresados (máximo 3 años anteriores al cierre de la convocatoria) de la Universidad El Bosque a través de la figura de joven investigador. * Vinculación de estudiantes auxiliares de posgrado de la Universidad El Bosque.
A6: Nombre completo del Investigador | B6: Rol en el Proyecto (Investigador Principal - Co-Investigador - Joven Investigador) | C6: Unidad Academica | D6: Categoría o Escalafón | E6: Tipo de Vinculación (Laboral Prestacion de Servicios Ad-honorem) | F6: Función/Justificación | G6: Cantidad | H6: Meses de dedicación | I6: Dedicación Hr/semana | J6: Año 1 | M6: Año 2 | P6: Año 3 | S6: Total | T6: Universidad El Bosque | V6: Nombre de entidad co-ejecutora | X6: Total
J7: Valor mensual | K7: Meses | L7: Valor total en especie | M7: Valor mensual | N7: Meses | O7: Valor total en especie | P7: Valor mensual | Q7: Meses | R7: Valor total en especie | T7: Dinero (RECURSOS CONVOCATORIA INTERNA EFECTIVO) | U7: Especie (RECURSOS CONVOCATORIA INTERNA ESPECIE) | V7: Dinero | W7: Especie
A8: Juan David Leongómez Peña | B8: Investigador Principal | C8: Facultad de Psicología | D8: Profesor Asociado | E8: Laboral | F8: Diseño, análisis y modelado estadístico, manipulación acústica, análisis acústico, dirección general, coordinación, supervisión de análisis, escritura de publicaciones y actividades de divulgación. | G8: 1 | H8: 30 | I8: 10 | J8: 3137055.7 | K8: 11 | L8: =J8*K8 -> 34507613 | M8: 3388020.2 | N8: 11 | O8: =M8*N8 -> 37268222 | P8: 3659061.8 | Q8: 6 | R8: =P8*Q8 -> 21954371 | S8: =+L8+O8+R8 -> 93730206 | T8: 0 | U8: =S8 -> 93730206 | V8: 0 | W8: 0 | X8: =+T8+U8+V8+W8 -> 93730206
A9: Milena Vásquez-Amézquita | B9: Co-Investigadora | C9: Facultad de Psicología | D9: Profesor Asociada | E9: Laboral | F9: Coordinación de estudios con eye-tracking, apoyo en análisis, supervisión de semillero SexCog y 1 trabajo de grado, publicaciones. | G9: 1 | H9: 30 | I9: 6 | J9: 1882233.4 | K9: 11 | L9: =J9*K9 -> 20704568 | M9: 2032812.1 | N9: 11 | O9: =M9*N9 -> 22360933 | P9: 2195437.1 | Q9: 6 | R9: =P9*Q9 -> 13172622 | S9: =+L9+O9+R9 -> 56238123 | T9: 0 | U9: =S9 -> 56238123 | V9: 0 | W9: 0 | X9: =+T9+U9+V9+W9 -> 56238123
A10: Nicolás Ignacio Ramos Rodríguez | B10: Co-Investigador | C10: Facultad de Medicina | D10: Profesor Titular | E10: Laboral | F10: Propuestas de posibles aplicaciones clínicas y/o recomendaciones a cuidadores de bebés a partir de resultados. Reclutamiento de participantes. | G10: 1 | H10: 30 | I10: 2 | J10: 918947.78 | K10: 11 | L10: =J10*K10 -> 10108426 | M10: 992463.61 | N10: 11 | O10: =M10*N10 -> 10917100 | P10: 1071860.7 | Q10: 6 | R10: =P10*Q10 -> 6431164.2 | S10: =+L10+O10+R10 -> 27456689 | T10: 0 | U10: =S10 -> 27456689 | V10: 0 | W10: 0 | X10: =+T10+U10+V10+W10 -> 27456689
A11: María Catalina Bages Mesa | B11: Co-Investigadora | C11: Facultad de Medicina | D11: Profesora Titular | E11: Laboral | F11: Propuestas de posibles aplicaciones clínicas y/o recomendaciones a cuidadores de bebés a partir de resultados. Reclutamiento de participantes. | G11: 1 | H11: 30 | I11: 2 | J11: 510796.49 | K11: 11 | L11: =J11*K11 -> 5618761.4 | M11: 551660.21 | N11: 11 | O11: =M11*N11 -> 6068262.3 | P11: 595793.02 | Q11: 6 | R11: =P11*Q11 -> 3574758.1 | S11: =+L11+O11+R11 -> 15261782 | T11: 0 | U11: =S11 -> 15261782 | V11: 0 | W11: 0 | X11: =+T11+U11+V11+W11 -> 15261782
A12: Bertha Patricia Calderón Ortiz | B12: Co-Investigadora | C12: Facultad de Medicina | D12: Profesor Asociada | E12: Laboral | F12: Propuestas de posibles aplicaciones clínicas y/o recomendaciones a cuidadores de bebés a partir de resultados. Reclutamiento de participantes. | G12: 1 | H12: 30 | I12: 2 | J12: 510796.49 | K12: 11 | L12: =J12*K12 -> 5618761.4 | M12: 551660.21 | N12: 11 | O12: =M12*N12 -> 6068262.3 | P12: 595793.02 | Q12: 6 | R12: =P12*Q12 -> 3574758.1 | S12: =+L12+O12+R12 -> 15261782 | T12: 0 | U12: =S12 -> 15261782 | V12: 0 | W12: 0 | X12: =+T12+U12+V12+W12 -> 15261782
A13: Daniel Toro Avila | B13: Co-Investigador | C13: Externo (Independiente) | D13: NA | E13: Externo (colaboración personal) | F13: Propuestas de posibles aplicaciones clínicas y/o recomendaciones a cuidadores de bebés a partir de resultados. Reclutamiento de participantes. | G13: 1 | H13: 30 | I13: 0 | J13: 0 | K13: 11 | L13: =J13*K13 -> 0 | M13: 0 | N13: 11 | O13: =M13*N13 -> 0 | P13: 0 | Q13: 6 | R13: =P13*Q13 -> 0 | S13: =+L13+O13+R13 -> 0 | T13: 0 | U13: =S13 -> 0 | V13: 0 | W13: 0 | X13: =+T13+U13+V13+W13 -> 0
A14: Adriana María Cristancho Arévalo | B14: Co-Investigadora | C14: Facultad de Medicina | D14: Profesor Asociada | E14: Laboral | F14: Propuestas de posibles aplicaciones clínicas y/o recomendaciones a cuidadores de bebés a partir de resultados. Reclutamiento de participantes. | G14: 1 | H14: 30 | I14: 2 | J14: 409366.03 | K14: 11 | L14: =J14*K14 -> 4503026.4 | M14: 442115.31 | N14: 11 | O14: =M14*N14 -> 4863268.5 | P14: 477484.54 | Q14: 6 | R14: =P14*Q14 -> 2864907.2 | S14: =+L14+O14+R14 -> 12231202 | T14: 0 | U14: =S14 -> 12231202 | V14: 0 | W14: 0 | X14: =+T14+U14+V14+W14 -> 12231202
A15: Ruth Stella Chacon Pinilla | B15: Co-Investigadora | C15: Facultad de Educación | D15: Profesora Titular | E15: Laboral | F15: Apoyo teórico en educación infantil, supervisión estudiante de maestría, actividades de divulgación, publicaciones. | G15: 1 | H15: 30 | I15: 6 | J15: 2756843.4 | K15: 11 | L15: =J15*K15 -> 30325277 | M15: 2977390.8 | N15: 11 | O15: =M15*N15 -> 32751299 | P15: 3215582.1 | Q15: 6 | R15: =P15*Q16 -> 19293493 | S15: =+L15+O15+R15 -> 82370068 | T15: 0 | U15: =S15 -> 82370068 | V15: 0 | W15: 0 | X15: =+T15+U15+V15+W15 -> 82370068
A16: Lina Maria Rodríguez Granada | B16: Co-Investigadora | C16: Facultad de Psicología | D16: Profesora Asistente | E16: Laboral | F16: Bases teóricas desde psicología de la música, supervisión semillero Música y Psicología, actividades de divulgación, apoyo en análisis de Estudio 2 y publicaciones. | G16: 1 | H16: 30 | I16: 2 | J16: 510796.49 | K16: 11 | L16: =J16*K16 -> 5618761.4 | M16: 551660.21 | N16: 11 | O16: =M16*N16 -> 6068262.3 | P16: 595793.02 | Q16: 6 | R16: =P16*Q17 -> 3574758.1 | S16: =+L16+O16+R16 -> 15261782 | T16: 0 | U16: =S16 -> 15261782 | V16: 0 | W16: 0 | X16: =+T16+U16+V16+W16 -> 15261782
A17: Luz Helena Buitrago León | B17: Co-Investigadora | C17: Facultad de Psicología | D17: Profesora Titular | E17: Laboral | F17: Apoyo teórico en desarrollo infantil, supervisión estudiante de especialización, actividades de divulgación, publicaciones. | G17: 1 | H17: 30 | I17: 2 | J17: 918947.78 | K17: 11 | L17: =J17*K17 -> 10108426 | M17: 992463.61 | N17: 11 | O17: =M17*N17 -> 10917100 | P17: 1071860.7 | Q17: 6 | R17: =P17*Q18 -> 6431164.2 | S17: =+L17+O17+R17 -> 27456689 | T17: 0 | U17: =S17 -> 27456689 | V17: 0 | W17: 0 | X17: =+T17+U17+V17+W17 -> 27456689
A18: Natalia Moreno-Buitrago | B18: Co-Investigadora | C18: Externo (Ohio State University) | D18: NA | E18: Externo (colaboración personal) | F18: Apoyo para la medición de habilidades musicales y lingüísticas | G18: 1 | H18: 30 | I18: 0 | J18: 0 | K18: 11 | L18: =J18*K18 -> 0 | M18: 0 | N18: 11 | O18: =M18*N18 -> 0 | P18: 0 | Q18: 6 | R18: =P18*Q19 -> 0 | S18: =+L18+O18+R18 -> 0 | T18: 0 | U18: =S18 -> 0 | V18: 0 | W18: 0 | X18: =+T18+U18+V18+W18 -> 0
A19: David A. Puts | B19: Co-Investigador | C19: Externo (Pennsylvania State University) | D19: Profesor Titular | E19: Externo (colaboración personal) | F19: Apoyo al diseño general, análisis y manipulación acústica | G19: 1 | H19: 30 | I19: 0 | J19: 0 | K19: 11 | L19: =J19*K19 -> 0 | M19: 0 | N19: 11 | O19: =M19*N19 -> 0 | P19: 0 | Q19: 6 | R19: =P19*Q19 -> 0 | S19: =+L19+O19+R19 -> 0 | T19: 0 | U19: =S19 -> 0 | V19: 0 | W19: 0 | X19: =+T19+U19+V19+W19 -> 0
A20: Total | L20: =SUM(L8:L19) -> 1.2711362e+08 | O20: =SUM(O8:O19) -> 1.3728271e+08 | R20: =SUM(R8:R19) -> 80871996 | S20: =SUM(S8:S19) -> 3.4526832e+08 | T20: =SUM(T8:T19) -> 0 | U20: =SUM(U8:U19) -> 3.4526832e+08 | V20: =SUM(V8:V19) -> 0 | W20: =SUM(W8:W19) -> 0 | X20: =+T20+U20+V20+W20 -> 3.4526832e+08
A21: El calculo en especie se realiza tomando su sueldo según su categoría o escalafón docente, se divide en 40 horas y se multiplica por las horas semanales de dedicación al proyecto (ver pestaña BASES PERSONAL), proyectada a 11 meses por año.
A25: Salario Mínimo Vigente 2025 | B25: 1423500
A26: Incremento IPC sugerido | B26: 0.06
A27: Salarios Prestación de Servicios
A28: Formación | B28: SMLV | C28: Experiencia | D28: Valor
A29: Técnico | B29: 1 | C29: 1 a 5 años | D29: =+B29*$B$25 -> 1423500
A30: Tecnólogo | B30: 1.5 | C30: 1 a 5 años | D30: =+B30*$B$25 -> 2135250
A31: Profesional | B31: 2.5 | C31: 1 a 5 años | D31: =+B31*$B$25 -> 3558750
A32: Especialista | B32: 3.5 | C32: 1 a 5 años | D32: =+B32*$B$25 -> 4982250
A33: Magister | B33: 5 | C33: 1 a 5 años | D33: =+B33*$B$25 -> 7117500
A34: Doctorado | B34: 5.5 | C34: 1 a 5 años | D34: =+B34*$B$25 -> 7829250

Sheet Equipos especializados
A1: ='RESUMEN GENERAL'!A3 -> Título del proyecto: | B1: {='RESUMEN GENERAL'!B3:J3} -> Funciones evolutivas del habla dirigida a bebés: Impacto en la atención, las preferencias auditivas y el desarrollo lingüístico y musical temprano | C1: 0 | D1: 0 | E1: 0 | F1: 0 | G1: 0 | H1: 0 | I1: 0 | J1: 0
A2: ='RESUMEN GENERAL'!A4 -> Investigador Principal: | B2: {='RESUMEN GENERAL'!B4:J4} -> Juan David Leongómez Peña | C2: 0 | D2: 0 | E2: 0 | F2: 0 | G2: 0 | H2: 0 | I2: 0 | J2: 0
A4: Equipos
A5: Podrá solicitarse la compra de equipos, siempre y cuando respondan a la metodología planteada y fortalezcan futuros desarrollos en investigación. La compra de equipos deberá contar con el visto bueno de las respectivas coordinaciones de investigación de las unidades académicas, por lo tanto, deberán garantizar las instalaciones y las condiciones de ubicación, almacenamiento y mantenimiento de los equipos adquiridos. Notas: ● Al momento de solicitar la compra de equipos, deberá considerarse en la proyección del presupuesto los costos de impuestos, aranceles o bodegaje, en el caso que corresponda. ● En el caso de considerar compras de equipos en moneda extranjera (dólares, euros, francos etc), se sugiere realizar los ajustes correspondientes en el presupuesto, con el fin de evitar déficit al momento de realizar la ejecución.
A6: Equipo | B6: Justificación | C6: Cantidad | D6: Valor Unitario | E6: Universidad El Bosque | G6: Nombre de entidad co-ejecutora | I6: Total
E7: Dinero (RECURSOS CONVOCATORIA INTERNA EFECTIVO) | F7: Especie | G7: Dinero | H7: Especie
A8: EyeLink 1000 Plus | B8: Sistema de rastreo ocular de alta precisión, ideal para estudios con bebés gracias a su módulo remoto y montaje flexible, pero también apto para participantes de cualquier edad. Permite medir atención visual y respuestas pupilares en tareas audiovisuales. Incluye estación de trabajo, software y soporte técnico. El valor estimado para la compra del equipo (CA$47.430) fue convertido a pesos colombianos con una tasa de cambio proyectada de $3.600 COP por dólar canadiense, teniendo en cuenta posibles variaciones (+20%) en el tipo de cambio durante la ejecución del proyecto. Además, se adicionó un 40% sobre el valor resultante en pesos para cubrir costos relacionados con importación, impuestos, aranceles, nacionalización y bodegaje, según lo recomendado por la VRI. | C8: 1 | D8: 239000000 | E8: =D8 -> 239000000 | F8: 0 | G8: 0 | H8: 0 | I8: =SUM(E8:H8) -> 239000000
D9: 0 | E9: 0 | F9: 0 | G9: 0 | H9: 0 | I9: =SUM(E9:H9) -> 0
D10: 0 | E10: 0 | F10: 0 | G10: 0 | H10: 0 | I10: =SUM(E10:H10) -> 0
D11: 0 | E11: 0 | F11: 0 | G11: 0 | H11: 0 | I11: =SUM(E11:H11) -> 0
D12: 0 | E12: 0 | F12: 0 | G12: 0 | H12: 0 | I12: =SUM(E12:H12) -> 0
D13: 0 | E13: 0 | F13: 0 | G13: 0 | H13: 0 | I13: =SUM(E13:H13) -> 0
D14: 0 | E14: 0 | F14: 0 | G14: 0 | H14: 0 | I14: =SUM(E14:H14) -> 0
D15: 0 | E15: 0 | F15: 0 | G15: 0 | H15: 0 | I15: =SUM(E15:H15) -> 0
D16: 0 | E16: 0 | F16: 0 | G16: 0 | H16: 0 | I16: =SUM(E16:H16) -> 0
D17: 0 | E17: 0 | F17: 0 | G17: 0 | H17: 0 | I17: =SUM(E17:H17) -> 0
A18: Total | E18: =SUM(E8:E17) -> 239000000 | F18: =SUM(F8:F17) -> 0 | G18: =SUM(G8:G17) -> 0 | H18: =SUM(H8:H17) -> 0 | I18: =SUM(I8:I17) -> 239000000
A20: Especie UEB: Valor de uso de los equipos que se tienen disponibles para la investigación

Sheet Materiales y reactivos 
A1: ='RESUMEN GENERAL'!A3 -> Título del proyecto: | B1: {='RESUMEN GENERAL'!B3:J3} -> Funciones evolutivas del habla dirigida a bebés: Impacto en la atención, las preferencias auditivas y el desarrollo lingüístico y musical temprano | C1: 0 | D1: 0 | E1: 0 | F1: 0 | G1: 0 | H1: 0 | I1: 0 | J1: 0
A2: ='RESUMEN GENERAL'!A4 -> Investigador Principal: | B2: {='RESUMEN GENERAL'!B4:J4} -> Juan David Leongómez Peña | C2: 0 | D2: 0 | E2: 0 | F2: 0 | G2: 0 | H2: 0 | I2: 0 | J2: 0
A4: Materiales consumibles e insumos
A5: Insumos, consumibles y reactivos necesarios para el desarrollo de la investigación. Notas: * En el caso de considerar compras o contratar servicios en moneda extranjera, se sugiere realizar los ajustes correspondientes en el presupuesto, con el fin de evitar déficit al momento de realizar la ejecución. * Las propuestas que involucren el uso de sustancias químicas controladas (ver documento de consulta “Sustancias químicas controladas”), deberán especificar con exactitud la concentración y la cantidad requeridas durante todo el tiempo de ejecución. Lo anterior, acorde con la normativa nacional legal vigente.
A6: Materiales | B6: Justificación | C6: Cantidad | D6: Valor Unitario | E6: Total | F6: Universidad El Bosque | G6: Nombre de entidad co-ejecutora | I6: Total proyecto
F7: Dinero (RECURSOS CONVOCATORIA INTERNA EFECTIVO) | G7: Dinero | H7: Especie
E8: =+C8*D8 -> 0 | F8: 0 | I8: =SUM(F8:H8) -> 0
F9: 0
E10: =+C10*D10 -> 0 | F10: 0 | I10: =SUM(F10:H10) -> 0
E11: =+C11*D11 -> 0 | F11: 0 | I11: =SUM(F11:H11) -> 0
E12: =+C12*D12 -> 0 | F12: 0 | I12: =SUM(F12:H12) -> 0
E13: =+C13*D13 -> 0 | F13: 0 | I13: =SUM(F13:H13) -> 0
E14: =+C14*D14 -> 0 | F14: 0 | I14: =SUM(F14:H14) -> 0
E15: =+C15*D15 -> 0 | F15: 0 | I15: =SUM(F15:H15) -> 0
E16: =+C16*D16 -> 0 | F16: 0 | I16: =SUM(F16:H16) -> 0
A17: Total: | E17: =SUM(E8:E16) -> 0 | F17: =SUM(F8:F16) -> 0 | G17: =SUM(G8:G16) -> 0 | H17: =SUM(H8:H16) -> 0 | I17: =SUM(I8:I16) -> 0

Sheet Salida de campo
A1: ='RESUMEN GENERAL'!A3 -> Título del proyecto: | B1: {='RESUMEN GENERAL'!B3:J3} -> Funciones evolutivas del habla dirigida a bebés: Impacto en la atención, las preferencias auditivas y el desarrollo lingüístico y musical temprano | C1: 0 | D1: 0 | E1: 0 | F1: 0 | G1: 0 | H1: 0 | I1: 0 | J1: 0
A2: ='RESUMEN GENERAL'!A4 -> Investigador Principal: | B2: {='RESUMEN GENERAL'!B4:J4} -> Juan David Leongómez Peña | C2: 0 | D2: 0 | E2: 0 | F2: 0 | G2: 0 | H2: 0 | I2: 0 | J2: 0
A4: Salidas de Campo
A5: Gastos de viaje, transporte y estadía destinados exclusivamente a aquellas actividades que contemplan la recolección de muestras, entrevistas a poblaciones definidas, aplicación de instrumentos y demás actividades justificadas para el desarrollo de la propuesta que requieren desplazamiento dentro o fuera de Bogotá. Se aclara que, durante la ejecución de la propuesta, los gastos correspondientes a este rubro deberán soportarse con las respectivas facturas, únicamente del (los) sitio(s) de salida(s) de campo planteados en la metodología.
A6: Lugar | B6: Justificación | C6: Cantidad de Personas | D6: N° Viajes | E6: N° Dias | F6: N° de Noche | G6: Transporte - Pasajes (COP) | H6: Total Transporte - Pasajes (COP) | I6: Viaticos o gastos de viaje (COP) | J6: Total Viaticos o gastos de viaje (COP) | K6: Estadía (COP) | L6: Total Estadía (COP) | M6: Total viaje | N6: Universidad El Bosque | O6: Nombre de entidad co-ejecutora Dinero | Q6: Total proyecto
N7: Dinero (RECURSOS CONVOCATORIA INTERNA EFECTIVO) | O7: Dinero | P7: Especie
C8: 0 | D8: 0 | E8: 0 | F8: 0 | G8: 0 | H8: =+G8*C8*D8 -> 0 | I8: 0 | J8: =+C8*D8*E8*I8 -> 0 | K8: 0 | L8: =+C8*D8*F8*K8 -> 0 | M8: =+H8+J8+L8 -> 0 | N8: 0 | O8: 0 | P8: 0 | Q8: =SUM(N8:P8) -> 0
C9: 0 | D9: 0 | E9: 0 | F9: 0 | G9: 0 | H9: =+G9*C9*D9 -> 0 | I9: 0 | J9: =+C9*D9*E9*I9 -> 0 | K9: 0 | L9: =+C9*D9*F9*K9 -> 0 | M9: =+H9+J9+L9 -> 0 | N9: 0 | O9: 0 | P9: 0 | Q9: =SUM(N9:P9) -> 0
C10: 0 | D10: 0 | E10: 0 | F10: 0 | G10: 0 | H10: =+G10*C10*D10 -> 0 | I10: 0 | J10: =+C10*D10*E10*I10 -> 0 | K10: 0 | L10: =+C10*D10*F10*K10 -> 0 | M10: =+H10+J10+L10 -> 0 | N10: 0 | O10: 0 | P10: 0 | Q10: =SUM(N10:P10) -> 0
C11: 0 | D11: 0 | E11: 0 | F11: 0 | G11: 0 | H11: =+G11*C11*D11 -> 0 | I11: 0 | J11: =+C11*D11*E11*I11 -> 0 | K11: 0 | L11: =+C11*D11*F11*K11 -> 0 | M11: =+H11+J11+L11 -> 0 | N11: 0 | O11: 0 | P11: 0 | Q11: =SUM(N11:P11) -> 0
C12: 0 | D12: 0 | E12: 0 | F12: 0 | G12: 0 | H12: =+G12*C12*D12 -> 0 | I12: 0 | J12: =+C12*D12*E12*I12 -> 0 | K12: 0 | L12: =+C12*D12*F12*K12 -> 0 | M12: =+H12+J12+L12 -> 0 | N12: 0 | O12: 0 | P12: 0 | Q12: =SUM(N12:P12) -> 0
C13: 0 | D13: 0 | E13: 0 | F13: 0 | G13: 0 | H13: =+G13*C13*D13 -> 0 | I13: 0 | J13: =+C13*D13*E13*I13 -> 0 | K13: 0 | L13: =+C13*D13*F13*K13 -> 0 | M13: =+H13+J13+L13 -> 0 | N13: 0 | O13: 0 | P13: 0 | Q13: =SUM(N13:P13) -> 0
C14: 0 | D14: 0 | E14: 0 | F14: 0 | G14: 0 | H14: =+G14*C14*D14 -> 0 | I14: 0 | J14: =+C14*D14*E14*I14 -> 0 | K14: 0 | L14: =+C14*D14*F14*K14 -> 0 | M14: =+H14+J14+L14 -> 0 | N14: 0 | O14: 0 | P14: 0 | Q14: =SUM(N14:P14) -> 0
C15: 0 | D15: 0 | E15: 0 | F15: 0 | G15: 0 | H15: =+G15*C15*D15 -> 0 | I15: 0 | J15: =+C15*D15*E15*I15 -> 0 | K15: 0 | L15: =+C15*D15*F15*K15 -> 0 | M15: =+H15+J15+L15 -> 0 | N15: 0 | O15: 0 | P15: 0 | Q15: =SUM(N15:P15) -> 0
A16: TOTAL | H16: =SUM(H8:H15) -> 0 | J16: =SUM(J8:J15) -> 0 | L16: =SUM(L8:L15) -> 0 | M16: =SUM(M8:M15) -> 0 | N16: =SUM(N8:N15) -> 0 | O16: =SUM(O8:O15) -> 0 | P16: =SUM(P8:P15) -> 0 | Q16: =SUM(Q8:Q15) -> 0
A18: Valores de Referencia
A19: Destino | B19: Tiquetes | C19: Gastos de Viajes | D19: Hospedaje
A20: Nacional-Ciudades Princiales | B20: 600000 | C20: 80000 | D20: 150000
A21: Nacional-Otras | B21: 800000 | C21: 90000 | D21: 180000
A22: USA-Centro América | B22: 4000000 | C22: 180000 | D22: 400000
A23: EUROPA | B23: 6000000 | C23: 220000 | D23: 450000
A24: LATAM | B24: 3000000 | C24: 160000 | D24: 300000

Sheet Refrigerios
A1: ='RESUMEN GENERAL'!A3 -> Título del proyecto: | B1: {='RESUMEN GENERAL'!B3:J3} -> Funciones evolutivas del habla dirigida a bebés: Impacto en la atención, las preferencias auditivas y el desarrollo lingüístico y musical temprano | C1: 0 | D1: 0 | E1: 0 | F1: 0 | G1: 0 | H1: 0 | I1: 0 | J1: 0
A2: ='RESUMEN GENERAL'!A4 -> Investigador Principal: | B2: {='RESUMEN GENERAL'!B4:J4} -> Juan David Leongómez Peña | C2: 0 | D2: 0 | E2: 0 | F2: 0 | G2: 0 | H2: 0 | I2: 0 | J2: 0
A4: Refrigerios
A5: Únicamente se financiará este rubro para aquellas investigaciones que involucren procesos de participación comunitaria. Se entiende por refrigerio el suministro de pequeñas porciones de comida. Tenga en cuenta que no es ético condicionar la participación de la comunidad a cambio de incentivos. Abstenerse de solicitar este rubro para la financiación de alimentación (desayuno, onces, almuerzo o cena) de los investigadores en reuniones de trabajo y para la alimentación de la población objeto de estudio.
A8: Descripción | B8: Justificación | C8: Cantidad | D8: Valor Unitario | E8: Universidad El Bosque | F8: Nombre de entidad co-ejecutora | H8: Total proyecto
E9: Dinero (RECURSOS CONVOCATORIA INTERNA EFECTIVO) | F9: Dinero | G9: Especie
A10: Refrigerios para madres participantes en el Estudio 1 | B10: Se entregará un refrigerio y se reconocerá el transporte a cada madre al finalizar su sesión de participación con su bebé en el laboratorio, como parte de una estrategia de participación comunitaria que reconozca el esfuerzo de transportarse y asistir con un lactante. El valor estimado por refrigerio y transporte es de COP$40.000. Aunque se proyecta una muestra de 160 díadas, se calculan 200 refrigerios considerando que en algunos casos los datos no serán utilizables (por ejemplo, por llanto, somnolencia o fallos técnicos), y se requerirá invitar a más familias para completar la muestra planificada. | C10: 200 | D10: 40000 | E10: =C10*D10 -> 8000000 | F10: 0 | G10: 0 | H10: =SUM(E10:G10) -> 8000000
D11: 0 | E11: 0 | F11: 0 | G11: 0 | H11: =SUM(C11:D11) -> 0
D12: 0 | E12: 0 | F12: 0 | G12: 0 | H12: =SUM(C12:D12) -> 0
D13: 0 | E13: 0 | F13: 0 | G13: 0 | H13: =SUM(C13:D13) -> 0
D14: 0 | E14: 0 | F14: 0 | G14: 0 | H14: =SUM(C14:D14) -> 0
D15: 0 | E15: 0 | F15: 0 | G15: 0 | H15: =SUM(C15:D15) -> 0
D16: 0 | E16: 0 | F16: 0 | G16: 0 | H16: =SUM(C16:D16) -> 0
D17: 0 | E17: 0 | F17: 0 | G17: 0 | H17: =SUM(C17:D17) -> 0
A18: TOTALES | E18: =SUM(E10:E17) -> 8000000 | F18: =SUM(F10:F17) -> 0 | G18: =SUM(G10:G17) -> 0 | H18: =SUM(H10:H17) -> 8000000

Sheet Servicios técnicos
A1: ='RESUMEN GENERAL'!A3 -> Título del proyecto: | B1: {='RESUMEN GENERAL'!B3:J3} -> Funciones evolutivas del habla dirigida a bebés: Impacto en la atención, las preferencias auditivas y el desarrollo lingüístico y musical temprano | C1: 0 | D1: 0 | E1: 0 | F1: 0 | G1: 0 | H1: 0 | I1: 0 | J1: 0
A2: ='RESUMEN GENERAL'!A4 -> Investigador Principal: | B2: {='RESUMEN GENERAL'!B4:J4} -> Juan David Leongómez Peña | C2: 0 | D2: 0 | E2: 0 | F2: 0 | G2: 0 | H2: 0 | I2: 0 | J2: 0
A4: Servicios técnicos
A5: Corresponde a contrataciones que se hacen para la prestación de servicios especializados y cuya necesidad esté debidamente justificada, por ejemplo, metodologías que requieren el acceso a equipos de alta gama y para las cuales el grupo de investigación no cuenta con la capacidad instalada. Por lo anterior, podrá realizarse la contratación de personas naturales o jurídicas diferentes a las vinculadas en la propuesta para la prestación de servicios calificados profesionales, técnicos o de apoyo. En el caso de que la Universidad El Bosque o la IPS Salud Bosque cuenten con la oferta del servicio (modalidad prestación de servicios), se deberá privilegiar su selección por encima de terceros externos. Nota: * En el caso de considerar contratar servicios en moneda extranjera, se sugiere realizar los ajustes correspondientes en el presupuesto, con el fin de evitar déficit al momento de realizar la ejecución. * Para servicios internacionales, es necesario tener en cuenta la retención de la fuente del 20% (ej: análisis de laboratorio).
A6: Descripción | B6: Justificación | C6: Cantidad | D6: Valor Unitario | E6: Total | F6: Universidad El Bosque | G6: Nombre de entidad co-ejecutora | I6: Total proyecto
F7: Dinero (RECURSOS CONVOCATORIA INTERNA EFECTIVO) | G7: Dinero | H7: Especie
A8: Honorarios para apoyo en la recolección de datos del Estudio 1 | B8: Contratación por prestación de servicios de una persona con experiencia en el trabajo con bebés y sus cuidadores, encargada de apoyar la recolección de datos en entornos controlados. Su labor incluye recibir a las familias, asistir en el manejo y posicionamiento de los bebés durante las tareas, asegurar condiciones óptimas para la medición con eye-tracker, y acompañar a las madres durante la sesión. Se proyecta un pago mensual de COP$2.000.000, acorde con funciones especializadas de acompañamiento en primera infancia, y perfiles como auxiliar de enfermería o profesional en educación infantil. | C8: 12 | D8: 2000000 | E8: =+D8*C8 -> 24000000 | F8: =E8 -> 24000000 | G8: 0 | H8: 0 | I8: =SUM(F8:G8) -> 24000000
D9: 0 | E9: =+D9*C9 -> 0 | F9: 0 | G9: 0 | H9: 0 | I9: =SUM(F9:G9) -> 0
D10: 0 | E10: =+D10*C10 -> 0 | F10: 0 | G10: 0 | H10: 0 | I10: =SUM(F10:H10) -> 0
D11: 0 | E11: =+D11*C11 -> 0 | F11: 0 | G11: 0 | H11: 0 | I11: =SUM(F11:H11) -> 0
D12: 0 | E12: =+D12*C12 -> 0 | F12: 0 | G12: 0 | H12: 0 | I12: =SUM(F12:H12) -> 0
D13: 0 | E13: =+D13*C13 -> 0 | F13: 0 | G13: 0 | H13: 0 | I13: =SUM(F13:H13) -> 0
D14: 0 | E14: =+D14*C14 -> 0 | F14: 0 | G14: 0 | H14: 0 | I14: =SUM(F14:H14) -> 0
D15: 0 | E15: =+D15*C15 -> 0 | F15: 0 | G15: 0 | H15: 0 | I15: =SUM(F15:H15) -> 0
D16: 0 | E16: =+D16*C16 -> 0 | F16: 0 | G16: 0 | H16: 0 | I16: =SUM(F16:H16) -> 0
A17: TOTAL | E17: =SUM(E8:E16) -> 24000000 | F17: =SUM(F8:F16) -> 24000000 | G17: =SUM(G8:G16) -> 0 | H17: =SUM(H8:H16) -> 0 | I17: =SUM(I8:I16) -> 24000000

Sheet Software especializado 
A1: ='RESUMEN GENERAL'!A3 -> Título del proyecto: | B1: {='RESUMEN GENERAL'!B3:J3} -> Funciones evolutivas del habla dirigida a bebés: Impacto en la atención, las preferencias auditivas y el desarrollo lingüístico y musical temprano | C1: 0 | D1: 0 | E1: 0 | F1: 0 | G1: 0 | H1: 0 | I1: 0 | J1: 0
A2: ='RESUMEN GENERAL'!A4 -> Investigador Principal: | B2: {='RESUMEN GENERAL'!B4:J4} -> Juan David Leongómez Peña | C2: 0 | D2: 0 | E2: 0 | F2: 0 | G2: 0 | H2: 0 | I2: 0 | J2: 0
A4: Software
A5: Podrá financiarse la compra o renovación de licencias con plena justificación y en línea con el diseño metodológico estipulado en la propuesta. Nota: * Tenga en cuenta que para la adquisición de cualquier software se deberá contar con el VoBo de la Dirección de Tecnología. * Tenga en cuenta que la instalación de software se debe realizar en un equipo institucional * Para indicar en especie el uso de las licencias deben revisar con el Departamento de Tecnología que la licencia si este disponible.
A6: Nombre del software | B6: Justificación | C6: Cantidad | D6: Valor Unitario | E6: Total | F6: Universidad El Bosque | H6: Nombre de entidad co-ejecutora | J6: Total proyecto
F7: Dinero (RECURSOS CONVOCATORIA INTERNA EFECTIVO) | G7: Especie | H7: Dinero | I7: Especie
C8: 0 | D8: 0 | E8: =+D8*C8 -> 0 | F8: 0 | G8: 0 | H8: 0 | I8: 0 | J8: =SUM(F8:I8) -> 0
C9: 0 | D9: 0 | E9: =+D9*C9 -> 0 | F9: 0 | G9: 0 | H9: 0 | I9: 0 | J9: =SUM(F9:I9) -> 0
C10: 0 | D10: 0 | E10: =+D10*C10 -> 0 | F10: 0 | G10: 0 | H10: 0 | I10: 0 | J10: =SUM(F10:I10) -> 0
C11: 0 | D11: 0 | E11: =+D11*C11 -> 0 | F11: 0 | G11: 0 | H11: 0 | I11: 0 | J11: =SUM(F11:I11) -> 0
C12: 0 | D12: 0 | E12: =+D12*C12 -> 0 | F12: 0 | G12: 0 | H12: 0 | I12: 0 | J12: =SUM(F12:I12) -> 0
C13: 0 | D13: 0 | E13: =+D13*C13 -> 0 | F13: 0 | G13: 0 | H13: 0 | I13: 0 | J13: =SUM(F13:I13) -> 0
C14: 0 | D14: 0 | E14: =+D14*C14 -> 0 | F14: 0 | G14: 0 | H14: 0 | I14: 0 | J14: =SUM(F14:I14) -> 0
C15: 0 | D15: 0 | E15: =+D15*C15 -> 0 | F15: 0 | G15: 0 | H15: 0 | I15: 0 | J15: =SUM(F15:I15) -> 0
A16: TOTAL | E16: =SUM(E8:E15) -> 0 | F16: =SUM(F8:F15) -> 0 | G16: =SUM(G8:G15) -> 0 | H16: =SUM(H8:H15) -> 0 | I16: =SUM(I8:I15) -> 0 | J16: =SUM(F16:I16) -> 0

Sheet Pólizas para la realización de 
A1: ='RESUMEN GENERAL'!A3 -> Título del proyecto: | B1: {='RESUMEN GENERAL'!B3:J3} -> Funciones evolutivas del habla dirigida a bebés: Impacto en la atención, las preferencias auditivas y el desarrollo lingüístico y musical temprano | C1: 0 | D1: 0 | E1: 0 | F1: 0 | G1: 0 | H1: 0 | I1: 0 | J1: 0
A2: ='RESUMEN GENERAL'!A4 -> Investigador Principal: | B2: {='RESUMEN GENERAL'!B4:J4} -> Juan David Leongómez Peña | C2: 0 | D2: 0 | E2: 0 | F2: 0 | G2: 0 | H2: 0 | I2: 0 | J2: 0
A4: Pólizas para la realización de Ensayos Clínicos
A5: Este rubro deberá usarse para pagar la póliza todo riesgo que ampare el cubrimiento de los perjuicios que se generen en la ejecución de los proyectos de investigación que correspondan a ensayos clínicos sin medicamentos. La aseguradora definirá el valor de la póliza teniendo en cuenta los riesgos para participantes en los ensayos clínicos. Es importante recordar que la Universidad El Bosque cuenta con una Póliza de Responsabilidad civil Extracontractual que ampara los perjuicios patrimoniales contractuales y extracontractuales de todas las investigaciones que se realicen en la Institución donde participan sujetos humanos, pero excluyendo cualquier tipo de ensayo clínico.
A6: Descripción | B6: Justificación | C6: Cantidad | D6: Valor Unitario | E6: Universidad El Bosque | F6: Nombre de entidad co-ejecutora | G6: Total proyecto
E7: Dinero (RECURSOS CONVOCATORIA INTERNA EFECTIVO) | F7: Dinero
C8: 0 | D8: 0 | E8: 0 | F8: 0 | G8: =SUM(E8:F8) -> 0
C9: 0 | D9: 0 | E9: 0 | F9: 0 | G9: =SUM(E9:F9) -> 0
C10: 0 | D10: 0 | E10: 0 | F10: 0 | G10: =SUM(E10:F10) -> 0
C11: 0 | D11: 0 | E11: 0 | F11: 0 | G11: =SUM(E11:F11) -> 0
C12: 0 | D12: 0 | E12: 0 | F12: 0 | G12: =SUM(E12:F12) -> 0
C13: 0 | D13: 0 | E13: 0 | F13: 0 | G13: =SUM(E13:F13) -> 0
C14: 0 | D14: 0 | E14: 0 | F14: 0 | G14: =SUM(E14:F14) -> 0
C15: 0 | D15: 0 | E15: 0 | F15: 0 | G15: =SUM(E15:F15) -> 0
A16: TOTALES | E16: =SUM(E8:E15) -> 0 | F16: =SUM(F8:F15) -> 0 | G16: 0

Sheet Apoyo a la producción científic
A1: ='RESUMEN GENERAL'!A3 -> Título del proyecto: | B1: {='RESUMEN GENERAL'!B3:J3} -> Funciones evolutivas del habla dirigida a bebés: Impacto en la atención, las preferencias auditivas y el desarrollo lingüístico y musical temprano | C1: 0 | D1: 0 | E1: 0 | F1: 0 | G1: 0 | H1: 0 | I1: 0 | J1: 0
A2: ='RESUMEN GENERAL'!A4 -> Investigador Principal: | B2: {='RESUMEN GENERAL'!B4:J4} -> Juan David Leongómez Peña | C2: 0 | D2: 0 | E2: 0 | F2: 0 | G2: 0 | H2: 0 | I2: 0 | J2: 0
A4: Apoyo a la producción científica o artística
A5: * Apoyo a la traducción de textos científicos. Este rubro podrá ser destinado al pago del servicio de traducción y edición de documentos científicos a publicar (libros, capítulos de libro, artículos científicos a publicar en revistas indexadas en WoS o Scopus). * Pago de tasas para publicación. Se financiará el pago de las tasas para efectos de publicación de los artículos en revistas indexadas en ISI o Scopus de carácter no depredador. * Producción en Arte, Arquitectura y Diseño -AAD-. Para los productos de AAD tipo Top o A bajo este rubro se podrá financiar el pago de apoyo para la producción o divulgación de obras.
A6: Nombre de la publicación | B6: Justificación | C6: Cantidad | D6: Valor Unitario | E6: Total | F6: Universidad El Bosque | G6: Nombre de entidad co-ejecutora | H6: Total proyecto
F7: Dinero (RECURSOS CONVOCATORIA INTERNA EFECTIVO) | G7: Dinero
C8: 0 | D8: 0 | E8: =+C8*D8 -> 0 | F8: 0 | G8: 0 | H8: =SUM(F8:G8) -> 0
C9: 0 | D9: 0 | E9: =+C9*D9 -> 0 | F9: 0 | G9: 0 | H9: =SUM(F9:G9) -> 0
C10: 0 | D10: 0 | E10: =+C10*D10 -> 0 | F10: 0 | G10: 0 | H10: =SUM(F10:G10) -> 0
C11: 0 | D11: 0 | E11: =+C11*D11 -> 0 | F11: 0 | G11: 0 | H11: =SUM(F11:G11) -> 0
C12: 0 | D12: 0 | E12: =+C12*D12 -> 0 | F12: 0 | G12: 0 | H12: =SUM(F12:G12) -> 0
C13: 0 | D13: 0 | E13: =+C13*D13 -> 0 | F13: 0 | G13: 0 | H13: =SUM(F13:G13) -> 0
C14: 0 | D14: 0 | E14: =+C14*D14 -> 0 | F14: 0 | G14: 0 | H14: =SUM(F14:G14) -> 0
A15: TOTALES | E15: =SUM(E8:E14) -> 0 | F15: =SUM(F8:F14) -> 0 | G15: =SUM(G8:G14) -> 0 | H15: =SUM(H8:H14) -> 0
A17: Valores de Referencia
A18: Concepto | B18: Valor
A19: Publicación de Artículos Q1 | B19: 16000000
A20: Publicación de Artículos Q2 | B20: 8000000
A21: Publicación de Artículos Q3 | B21: 3000000
A22: Traducción | B22: 2000000
A23: Corrección de estilo | B23: 3000000

Sheet Apoyo a la difusión de resultad
A1: ='RESUMEN GENERAL'!A3 -> Título del proyecto: | B1: {='RESUMEN GENERAL'!B3:J3} -> Funciones evolutivas del habla dirigida a bebés: Impacto en la atención, las preferencias auditivas y el desarrollo lingüístico y musical temprano | C1: 0 | D1: 0 | E1: 0 | F1: 0 | G1: 0 | H1: 0 | I1: 0 | J1: 0
A2: ='RESUMEN GENERAL'!A4 -> Investigador Principal: | B2: {='RESUMEN GENERAL'!B4:J4} -> Juan David Leongómez Peña | C2: 0 | D2: 0 | E2: 0 | F2: 0 | G2: 0 | H2: 0 | I2: 0 | J2: 0
A4: Apoyo a la difusión de resultados derivados de actividades de CTeI
A5: Eventos especializados. En este rubro se podrán incorporar los gastos asociados a la inscripción y movilización para la participación como ponente en eventos científicos, con el propósito de presentar los resultados obtenidos en el proceso de investigación.
A6: Lugar/Evento | B6: Justificación | C6: Cantidad de Personas | D6: N° Viajes | E6: N° Dias | F6: N° de Noche | G6: Transporte - Pasajes (COP) | H6: Total Transporte - Pasajes (COP) | I6: Viaticos o gastos de viaje (COP) | J6: Total Viaticos o gastos de viaje (COP) | K6: Estadía (COP) | L6: Total Estadía (COP) | M6: Total viaje | N6: Universidad El Bosque | O6: Nombre de entidad co-ejecutora Dinero | Q6: Total proyecto
N7: Dinero (RECURSOS CONVOCATORIA INTERNA EFECTIVO) | O7: Dinero | P7: Especie
A8: Evento internacional – Latinoamérica (por definir) | B8: Participación como ponente en evento internacional en América Latina, por definir según afinidad temática y momento de avance del proyecto. | C8: 1 | D8: 1 | E8: 6 | F8: 5 | G8: 3000000 | H8: =+G8*C8*D8 -> 3000000 | I8: 160000 | J8: =+C8*D8*E8*I8 -> 960000 | K8: 300000 | L8: =+C8*D8*F8*K8 -> 1500000 | M8: =+H8+J8+L8 -> 5460000 | N8: =M8 -> 5460000 | Q8: =SUM(N8:P8) -> 5460000
A9: Evento internacional – Europa (por definir) | B9: Participación como ponente en evento internacional en Europa, por definir según resultados obtenidos y oportunidades de difusión científica. | C9: 1 | D9: 1 | E9: 6 | F9: 5 | G9: 6000000 | H9: =+G9*C9*D9 -> 6000000 | I9: 220000 | J9: =+C9*D9*E9*I9 -> 1320000 | K9: 450000 | L9: =+C9*D9*F9*K9 -> 2250000 | M9: =G9+K9 -> 6450000 | N9: =M9 -> 6450000 | Q9: =SUM(N9:P9) -> 6450000
A10: Evento nacional – ciudad principal (por definir) | B10: Participación como ponente en evento académico nacional, por definir según pertinencia temática y calendario académico del año de ejecución. | C10: 1 | D10: 1 | E10: 3 | F10: 2 | G10: 600000 | H10: =+G10*C10*D10 -> 600000 | I10: 80000 | J10: =+C10*D10*E10*I10 -> 240000 | K10: 150000 | L10: =+C10*D10*F10*K10 -> 300000 | M10: =G10+K10 -> 750000 | N10: =M10 -> 750000 | Q10: =SUM(N10:P10) -> 750000
H11: =+G11*C11*D11 -> 0 | J11: =+C11*D11*E11*I11 -> 0 | L11: =+C11*D11*F11*K11 -> 0 | M11: =G11+K11 -> 0 | Q11: =SUM(N11:P11) -> 0
H12: =+G12*C12*D12 -> 0 | J12: =+C12*D12*E12*I12 -> 0 | L12: =+C12*D12*F12*K12 -> 0 | M12: =G12+K12 -> 0 | Q12: =SUM(N12:P12) -> 0
H13: =+G13*C13*D13 -> 0 | J13: =+C13*D13*E13*I13 -> 0 | L13: =+C13*D13*F13*K13 -> 0 | M13: =G13+K13 -> 0 | Q13: =SUM(N13:P13) -> 0
H14: =+G14*C14*D14 -> 0 | J14: =+C14*D14*E14*I14 -> 0 | L14: =+C14*D14*F14*K14 -> 0 | M14: =G14+K14 -> 0 | Q14: =SUM(N14:P14) -> 0
H15: =+G15*C15*D15 -> 0 | J15: =+C15*D15*E15*I15 -> 0 | L15: =+C15*D15*F15*K15 -> 0 | M15: =G15+K15 -> 0 | Q15: =SUM(N15:P15) -> 0
H16: =+G16*C16*D16 -> 0 | J16: =+C16*D16*E16*I16 -> 0 | L16: =+C16*D16*F16*K16 -> 0 | M16: =G16+K16 -> 0 | Q16: =SUM(N16:P16) -> 0
A17: TOTAL | H17: =SUM(H8:H16) -> 9600000 | J17: =SUM(J8:J16) -> 2520000 | L17: =SUM(L8:L16) -> 4050000 | M17: =SUM(M8:M16) -> 12660000 | N17: =SUM(N8:N16) -> 12660000 | O17: =SUM(O8:O16) -> 0 | P17: =SUM(P8:P16) -> 0 | Q17: =SUM(Q8:Q16) -> 12660000
A20: Valores de Referencia
A21: Destino | B21: Tiquetes | C21: Gastos de Viajes | D21: Hospedaje
A22: Nacional-Ciudades Princiales | B22: 600000 | C22: 80000 | D22: 150000
A23: Nacional-Otras | B23: 800000 | C23: 90000 | D23: 180000
A24: USA-Centro América | B24: 4000000 | C24: 180000 | D24: 400000
A25: EUROPA | B25: 6000000 | C25: 220000 | D25: 450000
A26: LATAM | B26: 3000000 | C26: 160000 | D26: 300000

Sheet Otros gastos
A1: ='RESUMEN GENERAL'!A3 -> Título del proyecto: | B1: {='RESUMEN GENERAL'!B3:J3} -> Funciones evolutivas del habla dirigida a bebés: Impacto en la atención, las preferencias auditivas y el desarrollo lingüístico y musical temprano | C1: 0 | D1: 0 | E1: 0 | F1: 0 | G1: 0 | H1: 0 | I1: 0 | J1: 0
A2: ='RESUMEN GENERAL'!A4 -> Investigador Principal: | B2: {='RESUMEN GENERAL'!B4:J4} -> Juan David Leongómez Peña | C2: 0 | D2: 0 | E2: 0 | F2: 0 | G2: 0 | H2: 0 | I2: 0 | J2: 0
A4: Otros gastos
A5: En este rubro solamente se pueden incluir gastos de envío de muestras, pago de tasas en el marco del permiso de colecta, licencias ambientales y gastos de correspondencia. Se excluye de la financiación todo gasto de operación indirecto tipo telefonía móvil, servicios públicos, pagos de matrícula, entre otros.
A7: Descripción | B7: Justificación | C7: Cantidad | D7: Valor Unitario | E7: Total | F7: Universidad El Bosque | G7: Nombre de entidad co-ejecutora | I7: Total proyecto
F8: Dinero (RECURSOS CONVOCATORIA INTERNA EFECTIVO) | G8: Dinero | H8: Especie
E9: =+D9*C9 -> 0 | I9: =SUM(F9:H9) -> 0
E10: =+D10*C10 -> 0 | I10: =SUM(F10:H10) -> 0
E11: =+D11*C11 -> 0 | I11: =SUM(F11:H11) -> 0
E12: =+D12*C12 -> 0 | I12: =SUM(F12:H12) -> 0
E13: =+D13*C13 -> 0 | I13: =SUM(F13:H13) -> 0
E14: =+D14*C14 -> 0 | I14: =SUM(F14:H14) -> 0
E15: =+D15*C15 -> 0 | I15: =SUM(F15:H15) -> 0
E16: =+D16*C16 -> 0 | I16: =SUM(F16:H16) -> 0
E17: =+D17*C17 -> 0 | I17: =SUM(F17:H17) -> 0
A18: TOTAL | E18: =SUM(E9:E17) -> 0 | F18: =SUM(F9:F17) -> 0 | G18: =SUM(G9:G17) -> 0 | H18: =SUM(H9:H17) -> 0 | I18: =SUM(I9:I17) -> 0

Sheet Estrategia de divulgación
A1: ='RESUMEN GENERAL'!A3 -> Título del proyecto: | B1: {='RESUMEN GENERAL'!B3:J3} -> Funciones evolutivas del habla dirigida a bebés: Impacto en la atención, las preferencias auditivas y el desarrollo lingüístico y musical temprano | C1: 0 | D1: 0 | E1: 0 | F1: 0 | G1: 0 | H1: 0 | I1: 0 | J1: 0
A2: ='RESUMEN GENERAL'!A4 -> Investigador Principal: | B2: {='RESUMEN GENERAL'!B4:J4} -> Juan David Leongómez Peña | C2: 0 | D2: 0 | E2: 0 | F2: 0 | G2: 0 | H2: 0 | I2: 0 | J2: 0
A4: Estrategia de Divulgación
A5: La financiación se destinará a la conceptualización, producción y edición de contenidos (videos, cápsulas, podcasts, infografías y textos), excluyendo asesorías de diseño, reclutamiento, socialización de resultados y logística, que se gestionan de forma independiente. Su objetivo es maximizar el impacto mediante estrategias transmedia y difusión en múltiples canales digitales. En el caso de que la Unidad de Divulgación y Cultura Científica (UDCC) de la Vicerrectoría de Investigaciones de la Universidad El Bosque cuente con la oferta del servicio se deberá privilegiar su selección por encima de terceros externos.
A7: Nombre del software | B7: Justificación | C7: Cantidad | D7: Valor Unitario | E7: Total | F7: Universidad El Bosque | G7: Nombre de entidad co-ejecutora | I7: Total proyecto
F8: Dinero (RECURSOS CONVOCATORIA INTERNA EFECTIVO) | G8: Dinero | H8: Especie
A9: Sitio web con información sobre IDS para madres, padres, cuidadores y personal de salud. | B9: Diseño e implementación de un sitio web informativo con contenidos accesibles sobre el habla dirigida a bebés (IDS), dirigido a madres, padres, cuidadores y personal de salud. Incluirá secciones sobre los beneficios de la IDS, materiales visuales y enlaces a recursos de divulgación. El valor cubre el dominio, el alojamiento y el desarrollo inicial del sitio. | C9: 1 | D9: 5000000 | E9: =+D9*C9 -> 5000000 | F9: =E9 -> 5000000 | I9: =SUM(F9:H9) -> 5000000
A10: Video/podcast sobre el vínculo afectivo y la IDS, las formas de la IDS y la pertinencia de abordaje desde el contexto familiar. | B10: Producción de video/podcast orientado a divulgar de forma clara y atractiva la importancia del habla dirigida a bebés, su vínculo con el afecto y su expresión en el entorno familiar. El valor cubre la escritura de guión, grabación, edición, diseño gráfico y publicación en plataformas accesibles. | C10: 2 | D10: 3000000 | E10: =+D10*C10 -> 6000000 | F10: =E10 -> 6000000 | I10: =SUM(F10:H10) -> 6000000
E11: =+D11*C11 -> 0 | I11: =SUM(F11:H11) -> 0
E12: =+D12*C12 -> 0 | I12: =SUM(F12:H12) -> 0
E13: =+D13*C13 -> 0 | I13: =SUM(F13:H13) -> 0
E14: =+D14*C14 -> 0 | I14: =SUM(F14:H14) -> 0
E15: =+D15*C15 -> 0 | I15: =SUM(F15:H15) -> 0
E16: =+D16*C16 -> 0 | I16: =SUM(F16:H16) -> 0
E17: =+D17*C17 -> 0 | I17: =SUM(F17:H17) -> 0
A18: TOTAL | E18: =SUM(E9:E17) -> 11000000 | F18: =SUM(F9:F17) -> 11000000 | G18: =SUM(G9:G17) -> 0 | H18: =SUM(H9:H17) -> 0 | I18: =SUM(F18:H18) -> 11000000
